Traceback (most recent call last):
  File "C:\Users\Hp\AppData\Local\Programs\Python\Python310\lib\site-packages\jupyter_cache\executors\utils.py", line 58, in single_nb_execution
    executenb(
  File "C:\Users\Hp\AppData\Local\Programs\Python\Python310\lib\site-packages\nbclient\client.py", line 1265, in execute
    return NotebookClient(nb=nb, resources=resources, km=km, **kwargs).execute()
  File "C:\Users\Hp\AppData\Local\Programs\Python\Python310\lib\site-packages\jupyter_core\utils\__init__.py", line 166, in wrapped
    return loop.run_until_complete(inner)
  File "C:\Users\Hp\AppData\Local\Programs\Python\Python310\lib\asyncio\base_events.py", line 646, in run_until_complete
    return future.result()
  File "C:\Users\Hp\AppData\Local\Programs\Python\Python310\lib\site-packages\nbclient\client.py", line 703, in async_execute
    await self.async_execute_cell(
  File "C:\Users\Hp\AppData\Local\Programs\Python\Python310\lib\site-packages\nbclient\client.py", line 1021, in async_execute_cell
    await self._check_raise_for_error(cell, cell_index, exec_reply)
  File "C:\Users\Hp\AppData\Local\Programs\Python\Python310\lib\site-packages\nbclient\client.py", line 915, in _check_raise_for_error
    raise CellExecutionError.from_cell_and_msg(cell, exec_reply_content)
nbclient.exceptions.CellExecutionError: An error occurred while executing the following cell:
------------------
df_1 = _deepnote_execute_sql('SELECT * FROM `defaultdb`.`dataset`', 'SQL_BC3F0200_03FA_4DF4_B292_41D7A332FCDA', audit_sql_comment='', sql_cache_mode='cache_disabled')
df_1
------------------

[1;31m---------------------------------------------------------------------------[0m
[1;31mNameError[0m                                 Traceback (most recent call last)
Cell [1;32mIn[1], line 1[0m
[1;32m----> 1[0m df_1 [38;5;241m=[39m [43m_deepnote_execute_sql[49m([38;5;124m'[39m[38;5;124mSELECT * FROM `defaultdb`.`dataset`[39m[38;5;124m'[39m, [38;5;124m'[39m[38;5;124mSQL_BC3F0200_03FA_4DF4_B292_41D7A332FCDA[39m[38;5;124m'[39m, audit_sql_comment[38;5;241m=[39m[38;5;124m'[39m[38;5;124m'[39m, sql_cache_mode[38;5;241m=[39m[38;5;124m'[39m[38;5;124mcache_disabled[39m[38;5;124m'[39m)
[0;32m      2[0m df_1

[1;31mNameError[0m: name '_deepnote_execute_sql' is not defined
NameError: name '_deepnote_execute_sql' is not defined

